Watching for file changes with StatReloader
C:\Users\user\Desktop\Django\HW\HW_proj\apphw\urls.py changed, reloading.
Watching for file changes with StatReloader
C:\Users\user\Desktop\Django\HW\HW_proj\apphw\urls.py changed, reloading.
Watching for file changes with StatReloader
C:\Users\user\Desktop\Django\HW\HW_proj\apphw\urls.py changed, reloading.
Watching for file changes with StatReloader
Посещена главная страница. IP: 127.0.0.1, User-Agent: Mozilla/5.0 (Windows NT 10.0; Win64; x64) AppleWebKit/537.36 (KHTML, like Gecko) Chrome/123.0.0.0 Safari/537.36
"GET / HTTP/1.1" 200 344
Посещена главная страница. IP: 127.0.0.1, User-Agent: Mozilla/5.0 (Windows NT 10.0; Win64; x64) AppleWebKit/537.36 (KHTML, like Gecko) Chrome/123.0.0.0 Safari/537.36
"GET / HTTP/1.1" 200 344
"GET /about HTTP/1.1" 301 0
Посещена страница 'О себе'. IP: 127.0.0.1, User-Agent: Mozilla/5.0 (Windows NT 10.0; Win64; x64) AppleWebKit/537.36 (KHTML, like Gecko) Chrome/123.0.0.0 Safari/537.36
"GET /about/ HTTP/1.1" 200 320
C:\Users\user\Desktop\Django\HW\HW_proj\apphw\views.py changed, reloading.
Watching for file changes with StatReloader
C:\Users\user\Desktop\Django\HW\HW_proj\apphw\views.py changed, reloading.
Watching for file changes with StatReloader
C:\Users\user\Desktop\Django\HW\HW_proj\apphw\views.py changed, reloading.
Watching for file changes with StatReloader
Watching for file changes with StatReloader
VISIT MAIN PAGE IP: 127.0.0.1, User-Agent: Mozilla/5.0 (Windows NT 10.0; Win64; x64) AppleWebKit/537.36 (KHTML, like Gecko) Chrome/123.0.0.0 Safari/537.36
"GET / HTTP/1.1" 200 206
VISIT ABOUT PAGE 'О себе'. IP: 127.0.0.1, User-Agent: Mozilla/5.0 (Windows NT 10.0; Win64; x64) AppleWebKit/537.36 (KHTML, like Gecko) Chrome/123.0.0.0 Safari/537.36
"GET /about/ HTTP/1.1" 200 194
C:\Users\user\Desktop\Django\HW\HW_proj\apphw\views.py changed, reloading.
Watching for file changes with StatReloader
C:\Users\user\Desktop\Django\HW\HW_proj\apphw\views.py changed, reloading.
Watching for file changes with StatReloader
C:\Users\user\Desktop\Django\HW\HW_proj\apphw\views.py changed, reloading.
Watching for file changes with StatReloader
C:\Users\user\Desktop\Django\HW\HW_proj\apphw\views.py changed, reloading.
Watching for file changes with StatReloader
Watching for file changes with StatReloader
C:\Users\user\Desktop\Django\HW\HW_proj\apphw\models.py changed, reloading.
Watching for file changes with StatReloader
C:\Users\user\Desktop\Django\HW\HW_proj\apphw\models.py changed, reloading.
Watching for file changes with StatReloader
C:\Users\user\Desktop\Django\HW\HW_proj\apphw\models.py changed, reloading.
Watching for file changes with StatReloader
C:\Users\user\Desktop\Django\HW\HW_proj\apphw\models.py changed, reloading.
Watching for file changes with StatReloader
C:\Users\user\Desktop\Django\HW\HW_proj\apphw\models.py changed, reloading.
Watching for file changes with StatReloader
C:\Users\user\Desktop\Django\HW\HW_proj\apphw\models.py changed, reloading.
Watching for file changes with StatReloader
C:\Users\user\Desktop\Django\HW\HW_proj\apphw\models.py changed, reloading.
Watching for file changes with StatReloader
C:\Users\user\Desktop\Django\HW\HW_proj\apphw\models.py changed, reloading.
Watching for file changes with StatReloader
Watching for file changes with StatReloader
"GET / HTTP/1.1" 200 10629
Not Found: /favicon.ico
"GET /favicon.ico HTTP/1.1" 404 2111
Watching for file changes with StatReloader
C:\Users\user\Desktop\Django\HW\HW_proj\apphw\models.py changed, reloading.
Watching for file changes with StatReloader
Watching for file changes with StatReloader
Not Found: /
"GET / HTTP/1.1" 404 3263
"GET /create_client/ HTTP/1.1" 200 1268
C:\Users\user\Desktop\Django\HW\HW_proj\apphw\forms.py changed, reloading.
Watching for file changes with StatReloader
"GET /create_client/ HTTP/1.1" 200 1092
"POST /create_client/ HTTP/1.1" 200 1249
"POST /create_client/ HTTP/1.1" 200 1249
C:\Users\user\Desktop\Django\HW\HW_proj\apphw\models.py changed, reloading.
Watching for file changes with StatReloader
Internal Server Error: /create_client/
Traceback (most recent call last):
  File "C:\Users\user\Desktop\Django\django_venv\Lib\site-packages\django\db\backends\utils.py", line 105, in _execute
    return self.cursor.execute(sql, params)
           ^^^^^^^^^^^^^^^^^^^^^^^^^^^^^^^^
  File "C:\Users\user\Desktop\Django\django_venv\Lib\site-packages\django\db\backends\sqlite3\base.py", line 329, in execute
    return super().execute(query, params)
           ^^^^^^^^^^^^^^^^^^^^^^^^^^^^^^
sqlite3.OperationalError: no such table: apphw_client

The above exception was the direct cause of the following exception:

Traceback (most recent call last):
  File "C:\Users\user\Desktop\Django\django_venv\Lib\site-packages\django\core\handlers\exception.py", line 55, in inner
    response = get_response(request)
               ^^^^^^^^^^^^^^^^^^^^^
  File "C:\Users\user\Desktop\Django\django_venv\Lib\site-packages\django\core\handlers\base.py", line 197, in _get_response
    response = wrapped_callback(request, *callback_args, **callback_kwargs)
               ^^^^^^^^^^^^^^^^^^^^^^^^^^^^^^^^^^^^^^^^^^^^^^^^^^^^^^^^^^^^
  File "C:\Users\user\Desktop\Django\HW\HW_proj\apphw\views.py", line 29, in create_client
    form.save()
  File "C:\Users\user\Desktop\Django\django_venv\Lib\site-packages\django\forms\models.py", line 552, in save
    self.instance.save()
  File "C:\Users\user\Desktop\Django\django_venv\Lib\site-packages\django\db\models\base.py", line 822, in save
    self.save_base(
  File "C:\Users\user\Desktop\Django\django_venv\Lib\site-packages\django\db\models\base.py", line 909, in save_base
    updated = self._save_table(
              ^^^^^^^^^^^^^^^^^
  File "C:\Users\user\Desktop\Django\django_venv\Lib\site-packages\django\db\models\base.py", line 1067, in _save_table
    results = self._do_insert(
              ^^^^^^^^^^^^^^^^
  File "C:\Users\user\Desktop\Django\django_venv\Lib\site-packages\django\db\models\base.py", line 1108, in _do_insert
    return manager._insert(
           ^^^^^^^^^^^^^^^^
  File "C:\Users\user\Desktop\Django\django_venv\Lib\site-packages\django\db\models\manager.py", line 87, in manager_method
    return getattr(self.get_queryset(), name)(*args, **kwargs)
           ^^^^^^^^^^^^^^^^^^^^^^^^^^^^^^^^^^^^^^^^^^^^^^^^^^^
  File "C:\Users\user\Desktop\Django\django_venv\Lib\site-packages\django\db\models\query.py", line 1847, in _insert
    return query.get_compiler(using=using).execute_sql(returning_fields)
           ^^^^^^^^^^^^^^^^^^^^^^^^^^^^^^^^^^^^^^^^^^^^^^^^^^^^^^^^^^^^^
  File "C:\Users\user\Desktop\Django\django_venv\Lib\site-packages\django\db\models\sql\compiler.py", line 1823, in execute_sql
    cursor.execute(sql, params)
  File "C:\Users\user\Desktop\Django\django_venv\Lib\site-packages\django\db\backends\utils.py", line 122, in execute
    return super().execute(sql, params)
           ^^^^^^^^^^^^^^^^^^^^^^^^^^^^
  File "C:\Users\user\Desktop\Django\django_venv\Lib\site-packages\django\db\backends\utils.py", line 79, in execute
    return self._execute_with_wrappers(
           ^^^^^^^^^^^^^^^^^^^^^^^^^^^^
  File "C:\Users\user\Desktop\Django\django_venv\Lib\site-packages\django\db\backends\utils.py", line 92, in _execute_with_wrappers
    return executor(sql, params, many, context)
           ^^^^^^^^^^^^^^^^^^^^^^^^^^^^^^^^^^^^
  File "C:\Users\user\Desktop\Django\django_venv\Lib\site-packages\django\db\backends\utils.py", line 100, in _execute
    with self.db.wrap_database_errors:
  File "C:\Users\user\Desktop\Django\django_venv\Lib\site-packages\django\db\utils.py", line 91, in __exit__
    raise dj_exc_value.with_traceback(traceback) from exc_value
  File "C:\Users\user\Desktop\Django\django_venv\Lib\site-packages\django\db\backends\utils.py", line 105, in _execute
    return self.cursor.execute(sql, params)
           ^^^^^^^^^^^^^^^^^^^^^^^^^^^^^^^^
  File "C:\Users\user\Desktop\Django\django_venv\Lib\site-packages\django\db\backends\sqlite3\base.py", line 329, in execute
    return super().execute(query, params)
           ^^^^^^^^^^^^^^^^^^^^^^^^^^^^^^
django.db.utils.OperationalError: no such table: apphw_client
"POST /create_client/ HTTP/1.1" 500 153758
Watching for file changes with StatReloader
Not Found: /
"GET / HTTP/1.1" 404 3263
"GET /create_client/ HTTP/1.1" 200 1115
Internal Server Error: /create_client/
Traceback (most recent call last):
  File "C:\Users\user\Desktop\Django\django_venv\Lib\site-packages\django\db\backends\utils.py", line 105, in _execute
    return self.cursor.execute(sql, params)
           ^^^^^^^^^^^^^^^^^^^^^^^^^^^^^^^^
  File "C:\Users\user\Desktop\Django\django_venv\Lib\site-packages\django\db\backends\sqlite3\base.py", line 329, in execute
    return super().execute(query, params)
           ^^^^^^^^^^^^^^^^^^^^^^^^^^^^^^
sqlite3.OperationalError: no such table: apphw_client

The above exception was the direct cause of the following exception:

Traceback (most recent call last):
  File "C:\Users\user\Desktop\Django\django_venv\Lib\site-packages\django\core\handlers\exception.py", line 55, in inner
    response = get_response(request)
               ^^^^^^^^^^^^^^^^^^^^^
  File "C:\Users\user\Desktop\Django\django_venv\Lib\site-packages\django\core\handlers\base.py", line 197, in _get_response
    response = wrapped_callback(request, *callback_args, **callback_kwargs)
               ^^^^^^^^^^^^^^^^^^^^^^^^^^^^^^^^^^^^^^^^^^^^^^^^^^^^^^^^^^^^
  File "C:\Users\user\Desktop\Django\HW\HW_proj\apphw\views.py", line 29, in create_client
    form.save()
  File "C:\Users\user\Desktop\Django\django_venv\Lib\site-packages\django\forms\models.py", line 552, in save
    self.instance.save()
  File "C:\Users\user\Desktop\Django\django_venv\Lib\site-packages\django\db\models\base.py", line 822, in save
    self.save_base(
  File "C:\Users\user\Desktop\Django\django_venv\Lib\site-packages\django\db\models\base.py", line 909, in save_base
    updated = self._save_table(
              ^^^^^^^^^^^^^^^^^
  File "C:\Users\user\Desktop\Django\django_venv\Lib\site-packages\django\db\models\base.py", line 1067, in _save_table
    results = self._do_insert(
              ^^^^^^^^^^^^^^^^
  File "C:\Users\user\Desktop\Django\django_venv\Lib\site-packages\django\db\models\base.py", line 1108, in _do_insert
    return manager._insert(
           ^^^^^^^^^^^^^^^^
  File "C:\Users\user\Desktop\Django\django_venv\Lib\site-packages\django\db\models\manager.py", line 87, in manager_method
    return getattr(self.get_queryset(), name)(*args, **kwargs)
           ^^^^^^^^^^^^^^^^^^^^^^^^^^^^^^^^^^^^^^^^^^^^^^^^^^^
  File "C:\Users\user\Desktop\Django\django_venv\Lib\site-packages\django\db\models\query.py", line 1847, in _insert
    return query.get_compiler(using=using).execute_sql(returning_fields)
           ^^^^^^^^^^^^^^^^^^^^^^^^^^^^^^^^^^^^^^^^^^^^^^^^^^^^^^^^^^^^^
  File "C:\Users\user\Desktop\Django\django_venv\Lib\site-packages\django\db\models\sql\compiler.py", line 1823, in execute_sql
    cursor.execute(sql, params)
  File "C:\Users\user\Desktop\Django\django_venv\Lib\site-packages\django\db\backends\utils.py", line 122, in execute
    return super().execute(sql, params)
           ^^^^^^^^^^^^^^^^^^^^^^^^^^^^
  File "C:\Users\user\Desktop\Django\django_venv\Lib\site-packages\django\db\backends\utils.py", line 79, in execute
    return self._execute_with_wrappers(
           ^^^^^^^^^^^^^^^^^^^^^^^^^^^^
  File "C:\Users\user\Desktop\Django\django_venv\Lib\site-packages\django\db\backends\utils.py", line 92, in _execute_with_wrappers
    return executor(sql, params, many, context)
           ^^^^^^^^^^^^^^^^^^^^^^^^^^^^^^^^^^^^
  File "C:\Users\user\Desktop\Django\django_venv\Lib\site-packages\django\db\backends\utils.py", line 100, in _execute
    with self.db.wrap_database_errors:
  File "C:\Users\user\Desktop\Django\django_venv\Lib\site-packages\django\db\utils.py", line 91, in __exit__
    raise dj_exc_value.with_traceback(traceback) from exc_value
  File "C:\Users\user\Desktop\Django\django_venv\Lib\site-packages\django\db\backends\utils.py", line 105, in _execute
    return self.cursor.execute(sql, params)
           ^^^^^^^^^^^^^^^^^^^^^^^^^^^^^^^^
  File "C:\Users\user\Desktop\Django\django_venv\Lib\site-packages\django\db\backends\sqlite3\base.py", line 329, in execute
    return super().execute(query, params)
           ^^^^^^^^^^^^^^^^^^^^^^^^^^^^^^
django.db.utils.OperationalError: no such table: apphw_client
"POST /create_client/ HTTP/1.1" 500 155268
